#VRML_SIM R2023b utf8

EXTERNPROTO "https://raw.githubusercontent.com/cyberbotics/webots/R2023b/projects/objects/backgrounds/protos/TexturedBackground.proto"
EXTERNPROTO "https://raw.githubusercontent.com/cyberbotics/webots/R2023b/projects/objects/backgrounds/protos/TexturedBackgroundLight.proto"
EXTERNPROTO "https://raw.githubusercontent.com/cyberbotics/webots/R2023b/projects/objects/floors/protos/RectangleArena.proto"
EXTERNPROTO "https://raw.githubusercontent.com/cyberbotics/webots/R2023b/projects/objects/drinks/protos/Can.proto"
EXTERNPROTO "https://raw.githubusercontent.com/cyberbotics/webots/R2023b/projects/objects/fruits/protos/Apple.proto"
EXTERNPROTO "https://raw.githubusercontent.com/cyberbotics/webots/R2023b/projects/objects/fruits/protos/Orange.proto"
EXTERNPROTO "https://raw.githubusercontent.com/cyberbotics/webots/R2023b/projects/objects/kitchen/breakfast/protos/JamJar.proto"
EXTERNPROTO "https://raw.githubusercontent.com/cyberbotics/webots/R2023b/projects/objects/kitchen/breakfast/protos/CerealBox.proto"
EXTERNPROTO "https://raw.githubusercontent.com/cyberbotics/webots/R2023b/projects/objects/obstacles/protos/OilBarrel.proto"
EXTERNPROTO "https://raw.githubusercontent.com/cyberbotics/webots/R2023b/projects/objects/kitchen/breakfast/protos/BiscuitBox.proto"
EXTERNPROTO "https://raw.githubusercontent.com/cyberbotics/webots/R2023b/projects/objects/toys/protos/RubberDuck.proto"

WorldInfo {
  info [
    "Example use of a color Camera device with recognition capability."
  ]
  title "Camera Image Recognition"
}
Viewpoint {
  orientation 0.4230646872725633 -0.029951437962670063 -0.9056043185337272 3.0485443866044966
  position 1.457257424142112 0.1382764770695935 1.5513929722001025
}
TexturedBackground {
}
TexturedBackgroundLight {
}
RectangleArena {
  floorSize 1.5 1.5
}
Can {
  translation 0.267626 0.290201 0.06096171086093549
  rotation 0.5851009785413565 -0.8081419311128227 0.06755341654709034 9.461161334178885e-17
}
Can {
  translation -0.326272 -0.341474 0.06096171086093549
  rotation 0.5851009785413565 -0.8081419311128227 0.06755341654709034 9.461161334178885e-17
  name "can(1)"
}
Apple {
  translation -0.260886 0.22946 0.049764791394518226
}
Apple {
  translation -0.621889 0.56252 0.049764791394518226
  name "apple(1)"
}
DEF ORANGE Solid {
  translation -0.002188 -0.063045 0
  children [
    Orange {
      translation -0.187654 0.182317 0.04999764793150722
    }
  ]
  name "orange"
  recognitionColors [
    0.988235 0.686275 0.243137
  ]
}
DEF ORANGE Solid {
  translation 0.085807 -0.503005 0
  children [
    Orange {
      translation -0.187654 0.182317 0.04999764793150722
    }
  ]
  name "orange(1)"
  recognitionColors [
    0.988235 0.686275 0.243137
  ]
}
JamJar {
  translation -0.33681 0.078775 0
  mass 0
}
JamJar {
  translation 0.314033 -0.288298 0
  rotation 0 0 1 2.094395
  name "jam jar(1)"
  mass 0
}
CerealBox {
  translation -0.43865 0.194464 -0.00039201630959942446
  rotation 7.42900737646321e-17 1.260307722627545e-16 -1 0.523599
}
CerealBox {
  translation -0.450258993482811 0.4152999958509094 -0.00039220694597741357
  rotation -7.438330800907709e-08 -2.0088280332014296e-06 -0.9999999999979795 0.7853985634923095
  name "cereal box(1)"
}
OilBarrel {
  translation -0.28712 -0.211927 0.07
  rotation 0 0 1 -1.5707953071795862
  height 0.14
  radius 0.06
}
OilBarrel {
  translation -0.240466 -0.485864 0.07
  rotation 0 0 1 -1.5707953071795862
  name "oil barrel(1)"
  height 0.14
  radius 0.06
}
OilBarrel {
  translation -0.464787 -0.437183 0.07
  rotation 0 0 1 -1.5707953071795862
  name "oil barrel(2)"
  height 0.14
  radius 0.06
}
BiscuitBox {
  translation 0.5384121770599435 -0.27466816841412345 0.03984308800740199
  rotation 0.6947462352857393 -0.18615610946793437 -0.694747127711986 -2.773493129695837
}
RubberDuck {
  translation -0.243817 0.384468 0.020436910949152138
  rotation 8.636487449720478e-19 8.72526086072641e-18 1 -2.356195307179586
}
Robot {
  translation 0.08378202361527336 0.001030368294856612 -0.00023422313031707526
  rotation -0.014128008738161628 -0.0581468966738095 0.9982080633697064 -0.4774910959097527
  children [
    Pose {
      translation 0 0 0.0415
      children [
        Shape {
          appearance PBRAppearance {
            baseColor 0.0820075 0.364731 0.8
            roughness 1
            metalness 0
          }
          geometry DEF BODY Cylinder {
            height 0.08
            radius 0.045
          }
        }
      ]
    }
    HingeJoint {
      jointParameters HingeJointParameters {
        position -7.582493053666436
        axis 0 1 0
        anchor 0 0 0.025
      }
      device [
        RotationalMotor {
          name "left wheel motor"
          consumptionFactor 70
        }
        PositionSensor {
          name "left wheel sensor"
        }
      ]
      endPoint Solid {
        translation 0 0.04499999999999999 0.025
        rotation 0 -0.9999999999999999 0 0.0007924393067256703
        children [
          DEF WHEEL Pose {
            rotation -1 0 0 1.57
            children [
              Shape {
                appearance PBRAppearance {
                  baseColor 1 0 0
                  roughness 1
                  metalness 0
                }
                geometry Cylinder {
                  height 0.01
                  radius 0.025
                }
              }
            ]
          }
        ]
        name "left wheel"
        boundingObject USE WHEEL
        physics DEF PHYSICS_WHEEL Physics {
          density -1
          mass 0.05
        }
        linearVelocity -0.02984822301119697 0.015851840565669628 -2.3834249276639366e-08
        angularVelocity -0.7050931827791003 -1.3240622354871028 0.7546163269136752
      }
    }
    HingeJoint {
      jointParameters HingeJointParameters {
        position 7.5824597002764085
        axis 0 1 0
        anchor 0 0 0.025
      }
      device [
        RotationalMotor {
          name "right wheel motor"
          consumptionFactor 70
        }
        PositionSensor {
          name "right wheel sensor"
        }
      ]
      endPoint Solid {
        translation 0 -0.045 0.025
        rotation 0 1 0 2.9951097002764087
        children [
          USE WHEEL
        ]
        name "right wheel"
        boundingObject USE WHEEL
        physics USE PHYSICS_WHEEL
        linearVelocity 0.029847938798797588 -0.015949833714121963 -6.393043804573812e-08
        angularVelocity 0.7050917012739994 1.324057514599299 0.7546178705887873
      }
    }
    DistanceSensor {
      translation 0.042 0.02 0.063
      rotation 0 0 -1 -0.499205
      children [
        DEF SENSOR Pose {
          rotation 0 1 0 1.57
          children [
            Shape {
              appearance PBRAppearance {
                baseColor 0.975691 0.981481 0.0252992
                roughness 1
                metalness 0
              }
              geometry Cylinder {
                height 0.004
                radius 0.008
              }
            }
          ]
        }
      ]
      name "ds0"
      lookupTable [
        0 1024 0
        0.05 1024 0
        0.15 0 0
      ]
      numberOfRays 2
      aperture 1
    }
    DistanceSensor {
      translation 0.042 -0.02 0.063
      rotation 0 0 1 -0.500795
      children [
        USE SENSOR
      ]
      name "ds1"
      lookupTable [
        0 1024 0
        0.05 1024 0
        0.15 0 0
      ]
      numberOfRays 2
      aperture 1
    }
    Shape {
      appearance PBRAppearance {
        baseColor 0.8 0.8 0.8
        baseColorMap ImageTexture {
          url [
            "https://raw.githubusercontent.com/cyberbotics/webots/R2023b/projects/samples/devices/worlds/textures/mybot.png"
          ]
        }
        roughness 0.5
        metalness 0
      }
      geometry IndexedFaceSet {
        coord Coordinate {
          point [
            0.0435 -0.015 0.038
            0.0435 -0.015 0.023
            0.0455 0 0.023
            0.0435 0.015 0.023
            0.0435 0.015 0.038
            0.0455 0 0.038
          ]
        }
        texCoord TextureCoordinate {
          point [
            0 0
            0.5 0
            1 0
            1 1
            0.5 1
            0 1
          ]
        }
        coordIndex [
          0, 1, 2, 5, -1, 5, 2, 3, 4, -1
        ]
        texCoordIndex [
          5, 0, 1, 4, -1, 4, 1, 2, 3, -1
        ]
        creaseAngle 0.9
      }
    }
    Camera {
      translation 0.04 0 0.0915
      children [
        Pose {
          translation -0.015 0 0
          rotation 0 -1 0 1.57
          children [
            Shape {
              appearance PBRAppearance {
                roughness 1
                metalness 0
              }
              geometry Cylinder {
                height 0.03
                radius 0.01
              }
            }
          ]
        }
      ]
      fieldOfView 1.0472
      width 256
      height 128
      antiAliasing TRUE
      recognition Recognition {
        frameColor 0.929412 0.831373 0
        frameThickness 3
        segmentation TRUE
      }
    }
    Display {
      name "segmented image display"
      width 256
      height 128
    }
  ]
  name "MyBot"
  boundingObject Pose {
    translation 0 0 0.0415
    children [
      USE BODY
    ]
  }
  physics Physics {
    density -1
    mass 0.5
  }
  controller "camera_segmentation"
  linearVelocity 0.0001646119313730363 0.00026083572969467107 -2.0920888971571715e-08
  angularVelocity -7.379725185109145e-07 -2.3566726848422894e-06 0.7505265652573644
}
